Workbook

Sheet ToC
C3: Table of Contents
C6: Units
C7: Input Units | E7: Actuals
C8: Output Units | E8: Actuals
C9: Currency | E9: USD
C10: Units Scalar | E10: {=10^(_xlfn.SWITCH(ToC!$E$8,"Millions",6,"Thousands",3,"Billions",9,"Actuals",0)-_xlfn.SWITCH(ToC!$E$7,"Millions",6,"Thousands",3,"Billions",9,"Actuals",0))} -> 1
C11: Units Abbreviation | E11: {=_xlfn.SWITCH(ToC!$E$8,"Millions","Ms","Thousands","Ks","Billions","Bs","Actuals","Actuals")} -> Actuals
C12: Currency Symbol | E12: {=_xlfn.SWITCH(ToC!$E$9,"EUR","€","GBP","£","AUD","A$","CNY","CN¥","HKD","HK$","INR","₹","JPY","¥","KRW","₩","SGD","S$","CAD","C$","CHF","CHF","NZD","NZ$","SEK","SEK","NOK","NOK","$")} -> $
C14: Annualization
C15: MRR Annualization | E15: 12
C17: Waterfalls
C18: Waterfall Charts | E18: Consolidated view of all waterfall charts
C19: Annual Waterfall | E19: Annual waterfall analysis
C20: Quarterly Waterfall | E20: Quarterly waterfall analysis
C21: Rolling LTM Waterfall | E21: LTM waterfall analysis
C23: Customers
C24: Top Customers | E24: Consolidated customer ranking analysis

Sheet Checks
A1: Worksheet | B1: Check Name | C1: Sum | D1: Status | E1: Data Sum
A2: AnnualWaterfall | B2: ARR | C2: =ROUND(SUM('Annual Waterfall'!D68:G68),4) -> 0 | D2: =IF(ABS(C2)>0.01,"Fail",IF(OR(E2="",E2>0.000001),"Pass",IF(AND(E2=0,C2=0),"Pass (No Data)","No Data"))) -> Pass | E2: {=SUMPRODUCT(ABS('Annual Waterfall'!D15:G15))} -> 898837.68
A3: AnnualWaterfall | B3: CustomerCount | C3: =ROUND(SUM('Annual Waterfall'!D69:G69),4) -> 0 | D3: =IF(ABS(C3)>0.01,"Fail",IF(OR(E3="",E3>0.000001),"Pass",IF(AND(E3=0,C3=0),"Pass (No Data)","No Data"))) -> Pass | E3: {=SUMPRODUCT(ABS('Annual Waterfall'!D51:G51))} -> 323
A4: LTMWaterfall | B4: ARR | C4: =ROUND(SUM('LTM Waterfall'!D68:AB68),4) -> 0 | D4: =IF(ABS(C4)>0.01,"Fail",IF(OR(E4="",E4>0.000001),"Pass",IF(AND(E4=0,C4=0),"Pass (No Data)","No Data"))) -> Pass | E4: {=SUMPRODUCT(ABS('LTM Waterfall'!D15:AB15))} -> 5638312.3
A5: LTMWaterfall | B5: CustomerCount | C5: =ROUND(SUM('LTM Waterfall'!D69:AB69),4) -> 0 | D5: =IF(ABS(C5)>0.01,"Fail",IF(OR(E5="",E5>0.000001),"Pass",IF(AND(E5=0,C5=0),"Pass (No Data)","No Data"))) -> Pass | E5: {=SUMPRODUCT(ABS('LTM Waterfall'!D51:AB51))} -> 2008
A6: QuarterlyWaterfall | B6: ARR | C6: =ROUND(SUM('Quarterly Waterfall'!D81:P81),4) -> 0 | D6: =IF(ABS(C6)>0.01,"Fail",IF(OR(E6="",E6>0.000001),"Pass",IF(AND(E6=0,C6=0),"Pass (No Data)","No Data"))) -> Pass | E6: {=SUMPRODUCT(ABS('Quarterly Waterfall'!D15:P15))} -> 2932190
A7: QuarterlyWaterfall | B7: CustomerCount | C7: =ROUND(SUM('Quarterly Waterfall'!D82:P82),4) -> 0 | D7: =IF(ABS(C7)>0.01,"Fail",IF(OR(E7="",E7>0.000001),"Pass",IF(AND(E7=0,C7=0),"Pass (No Data)","No Data"))) -> Pass | E7: {=SUMPRODUCT(ABS('Quarterly Waterfall'!D62:P62))} -> 1057
A8: SourceData | B8: Total ARR (Churned Customers) | C8: =ROUND(SUM('Quikirr Data'!C110:AM110),4) -> 0 | D8: =IF(ABS(C8)>0.01,"Fail",IF(OR(E8="",E8>0.000001),"Pass",IF(AND(E8=0,C8=0),"Pass (No Data)","No Data"))) -> Pass | E8: =""
A9: SourceData | B9: Total ARR (Downsell Customers) | C9: =ROUND(SUM('Quikirr Data'!C109:AM109),4) -> 0 | D9: =IF(ABS(C9)>0.01,"Fail",IF(OR(E9="",E9>0.000001),"Pass",IF(AND(E9=0,C9=0),"Pass (No Data)","No Data"))) -> Pass | E9: =""
A10: SourceData | B10: Total ARR (New Customers) | C10: =ROUND(SUM('Quikirr Data'!C107:AM107),4) -> 0 | D10: =IF(ABS(C10)>0.01,"Fail",IF(OR(E10="",E10>0.000001),"Pass",IF(AND(E10=0,C10=0),"Pass (No Data)","No Data"))) -> Pass | E10: =""
A11: SourceData | B11: ARR - Overall | C11: =ROUND(SUM('Quikirr Data'!C106:AM106),4) -> 0 | D11: =IF(ABS(C11)>0.01,"Fail",IF(OR(E11="",E11>0.000001),"Pass",IF(AND(E11=0,C11=0),"Pass (No Data)","No Data"))) -> Pass | E11: =""
A12: SourceData | B12: Total ARR (Upsell Customers) | C12: =ROUND(SUM('Quikirr Data'!C108:AM108),4) -> 0 | D12: =IF(ABS(C12)>0.01,"Fail",IF(OR(E12="",E12>0.000001),"Pass",IF(AND(E12=0,C12=0),"Pass (No Data)","No Data"))) -> Pass | E12: =""
A13: TopCustomers | B13: Total ARR (All Customers) | C13: =ROUND(SUM('Top Customers'!F131:I131),4) -> 0 | D13: =IF(ABS(C13)>0.01,"Fail",IF(OR(E13="",E13>0.000001),"Pass",IF(AND(E13=0,C13=0),"Pass (No Data)","No Data"))) -> Pass | E13: {=SUMPRODUCT(ABS('Top Customers'!F27:I27))} -> 898837.68
A14: TopCustomers | B14: Top N + Other = Total ARR (All Customers) | C14: =ROUND(SUM('Top Customers'!F132:I132),4) -> 0 | D14: =IF(ABS(C14)>0.01,"Fail",IF(OR(E14="",E14>0.000001),"Pass",IF(AND(E14=0,C14=0),"Pass (No Data)","No Data"))) -> Pass | E14: {=SUMPRODUCT(ABS('Top Customers'!F27:I27))} -> 898837.68
A15: TopCustomers | B15: Total ARR (Churned Customers) | C15: =ROUND(SUM('Top Customers'!F139:I139),4) -> 0 | D15: =IF(ABS(C15)>0.01,"Fail",IF(OR(E15="",E15>0.000001),"Pass",IF(AND(E15=0,C15=0),"Pass (No Data)","No Data"))) -> Pass | E15: {=SUMPRODUCT(ABS('Top Customers'!F27:I27))} -> 898837.68
A16: TopCustomers | B16: Top N + Other = Total ARR (Churned Customers) | C16: =ROUND(SUM('Top Customers'!F140:I140),4) -> 0 | D16: =IF(ABS(C16)>0.01,"Fail",IF(OR(E16="",E16>0.000001),"Pass",IF(AND(E16=0,C16=0),"Pass (No Data)","No Data"))) -> Pass | E16: {=SUMPRODUCT(ABS('Top Customers'!F27:I27))} -> 898837.68
A17: TopCustomers | B17: Total ARR (Downsell Customers) | C17: =ROUND(SUM('Top Customers'!F137:I137),4) -> 0 | D17: =IF(ABS(C17)>0.01,"Fail",IF(OR(E17="",E17>0.000001),"Pass",IF(AND(E17=0,C17=0),"Pass (No Data)","No Data"))) -> Pass | E17: {=SUMPRODUCT(ABS('Top Customers'!F27:I27))} -> 898837.68
A18: TopCustomers | B18: Top N + Other = Total ARR (Downsell Customers) | C18: =ROUND(SUM('Top Customers'!F138:I138),4) -> 0 | D18: =IF(ABS(C18)>0.01,"Fail",IF(OR(E18="",E18>0.000001),"Pass",IF(AND(E18=0,C18=0),"Pass (No Data)","No Data"))) -> Pass | E18: {=SUMPRODUCT(ABS('Top Customers'!F27:I27))} -> 898837.68
A19: TopCustomers | B19: Total ARR (New Customers) | C19: =ROUND(SUM('Top Customers'!F133:I133),4) -> 0 | D19: =IF(ABS(C19)>0.01,"Fail",IF(OR(E19="",E19>0.000001),"Pass",IF(AND(E19=0,C19=0),"Pass (No Data)","No Data"))) -> Pass | E19: {=SUMPRODUCT(ABS('Top Customers'!F27:I27))} -> 898837.68
A20: TopCustomers | B20: Top N + Other = Total ARR (New Customers) | C20: =ROUND(SUM('Top Customers'!F134:I134),4) -> 0 | D20: =IF(ABS(C20)>0.01,"Fail",IF(OR(E20="",E20>0.000001),"Pass",IF(AND(E20=0,C20=0),"Pass (No Data)","No Data"))) -> Pass | E20: {=SUMPRODUCT(ABS('Top Customers'!F27:I27))} -> 898837.68
A21: TopCustomers | B21: Total ARR (Upsell Customers) | C21: =ROUND(SUM('Top Customers'!F135:I135),4) -> 0 | D21: =IF(ABS(C21)>0.01,"Fail",IF(OR(E21="",E21>0.000001),"Pass",IF(AND(E21=0,C21=0),"Pass (No Data)","No Data"))) -> Pass | E21: {=SUMPRODUCT(ABS('Top Customers'!F27:I27))} -> 898837.68
A22: TopCustomers | B22: Top N + Other = Total ARR (Upsell Customers) | C22: =ROUND(SUM('Top Customers'!F136:I136),4) -> 0 | D22: =IF(ABS(C22)>0.01,"Fail",IF(OR(E22="",E22>0.000001),"Pass",IF(AND(E22=0,C22=0),"Pass (No Data)","No Data"))) -> Pass | E22: {=SUMPRODUCT(ABS('Top Customers'!F27:I27))} -> 898837.68
A23: SourceData_Annual | B23: Tagging Consistency (Max 1 Tag per Customer-Period) | C23: =ROUND(SUM('Quikirr Data'!FP4:FS103),4) -> 0 | D23: =IF(ABS(C23)>0.01,"Fail",IF(OR(E23="",E23>0.000001),"Pass",IF(AND(E23=0,C23=0),"Pass (No Data)","No Data"))) -> Pass | E23: =""
A24: SourceData_Quarterly | B24: Tagging Consistency (Max 1 Tag per Customer-Period) | C24: =ROUND(SUM('Quikirr Data'!DW4:EI103),4) -> 0 | D24: =IF(ABS(C24)>0.01,"Fail",IF(OR(E24="",E24>0.000001),"Pass",IF(AND(E24=0,C24=0),"Pass (No Data)","No Data"))) -> Pass | E24: =""
A25: SourceData_RollingLTM | B25: Tagging Consistency (Max 1 Tag per Customer-Period) | C25: =ROUND(SUM('Quikirr Data'!LV4:MT103),4) -> 0 | D25: =IF(ABS(C25)>0.01,"Fail",IF(OR(E25="",E25>0.000001),"Pass",IF(AND(E25=0,C25=0),"Pass (No Data)","No Data"))) -> Pass | E25: =""
A26: Annual Waterfall | B26: Data Presence - ARR | C26: {=IFERROR(IF(SUMPRODUCT(ABS('Annual Waterfall'!D10:G15))<=0.000001,1,0),1)} -> 0 | D26: =IF(ABS(C26)>0.01,"Fail",IF(OR(E26="",E26>0.000001),"Pass",IF(AND(E26=0,C26=0),"Pass (No Data)","No Data"))) -> Pass | E26: {=SUMPRODUCT(ABS('Annual Waterfall'!D10:G15))} -> 1655311.7
A27: Annual Waterfall | B27: Data Presence - Customer Count | C27: {=IFERROR(IF(SUMPRODUCT(ABS('Annual Waterfall'!D48:G51))<=0.000001,1,0),1)} -> 0 | D27: =IF(ABS(C27)>0.01,"Fail",IF(OR(E27="",E27>0.000001),"Pass",IF(AND(E27=0,C27=0),"Pass (No Data)","No Data"))) -> Pass | E27: {=SUMPRODUCT(ABS('Annual Waterfall'!D48:G51))} -> 591
A28: Annual Waterfall | B28: Source Connectivity | C28: =0 -> 0 | D28: =IF(ABS(C28)>0.01,"Fail",IF(OR(E28="",E28>0.000001),"Pass",IF(AND(E28=0,C28=0),"Pass (No Data)","No Data"))) -> Pass | E28: =""
A29: Quarterly Waterfall | B29: Data Presence - ARR | C29: {=IFERROR(IF(SUMPRODUCT(ABS('Quarterly Waterfall'!D10:P15))<=0.000001,1,0),1)} -> 0 | D29: =IF(ABS(C29)>0.01,"Fail",IF(OR(E29="",E29>0.000001),"Pass",IF(AND(E29=0,C29=0),"Pass (No Data)","No Data"))) -> Pass | E29: {=SUMPRODUCT(ABS('Quarterly Waterfall'!D10:P15))} -> 5728310.9
A30: Quarterly Waterfall | B30: Data Presence - Customer Count | C30: {=IFERROR(IF(SUMPRODUCT(ABS('Quarterly Waterfall'!D59:P62))<=0.000001,1,0),1)} -> 0 | D30: =IF(ABS(C30)>0.01,"Fail",IF(OR(E30="",E30>0.000001),"Pass",IF(AND(E30=0,C30=0),"Pass (No Data)","No Data"))) -> Pass | E30: {=SUMPRODUCT(ABS('Quarterly Waterfall'!D59:P62))} -> 2061
A31: Quarterly Waterfall | B31: Source Connectivity | C31: =0 -> 0 | D31: =IF(ABS(C31)>0.01,"Fail",IF(OR(E31="",E31>0.000001),"Pass",IF(AND(E31=0,C31=0),"Pass (No Data)","No Data"))) -> Pass | E31: =""
A32: LTM Waterfall | B32: Data Presence - ARR | C32: {=IFERROR(IF(SUMPRODUCT(ABS('LTM Waterfall'!D10:AB15))<=0.000001,1,0),1)} -> 0 | D32: =IF(ABS(C32)>0.01,"Fail",IF(OR(E32="",E32>0.000001),"Pass",IF(AND(E32=0,C32=0),"Pass (No Data)","No Data"))) -> Pass | E32: {=SUMPRODUCT(ABS('LTM Waterfall'!D10:AB15))} -> 12008907
A33: LTM Waterfall | B33: Data Presence - Customer Count | C33: {=IFERROR(IF(SUMPRODUCT(ABS('LTM Waterfall'!D48:AB51))<=0.000001,1,0),1)} -> 0 | D33: =IF(ABS(C33)>0.01,"Fail",IF(OR(E33="",E33>0.000001),"Pass",IF(AND(E33=0,C33=0),"Pass (No Data)","No Data"))) -> Pass | E33: {=SUMPRODUCT(ABS('LTM Waterfall'!D48:AB51))} -> 4282
A34: LTM Waterfall | B34: Source Connectivity | C34: =0 -> 0 | D34: =IF(ABS(C34)>0.01,"Fail",IF(OR(E34="",E34>0.000001),"Pass",IF(AND(E34=0,C34=0),"Pass (No Data)","No Data"))) -> Pass | E34: =""
A35: AnnualWaterfall | B35: Data Presence - ARR | C35: {=IFERROR(IF(SUMPRODUCT(ABS('Annual Waterfall'!D10:G15))<=0.000001,1,0),1)} -> 0 | D35: =IF(ABS(C35)>0.01,"Fail",IF(OR(E35="",E35>0.000001),"Pass",IF(AND(E35=0,C35=0),"Pass (No Data)","No Data"))) -> Pass | E35: {=SUMPRODUCT(ABS('Annual Waterfall'!D10:G15))} -> 1655311.7
A36: AnnualWaterfall | B36: Data Presence - Customer Count | C36: {=IFERROR(IF(SUMPRODUCT(ABS('Annual Waterfall'!D48:G51))<=0.000001,1,0),1)} -> 0 | D36: =IF(ABS(C36)>0.01,"Fail",IF(OR(E36="",E36>0.000001),"Pass",IF(AND(E36=0,C36=0),"Pass (No Data)","No Data"))) -> Pass | E36: {=SUMPRODUCT(ABS('Annual Waterfall'!D48:G51))} -> 591
A37: AnnualWaterfall | B37: Source Connectivity | C37: =0 -> 0 | D37: =IF(ABS(C37)>0.01,"Fail",IF(OR(E37="",E37>0.000001),"Pass",IF(AND(E37=0,C37=0),"Pass (No Data)","No Data"))) -> Pass | E37: =""
A38: LTMWaterfall | B38: Data Presence - ARR | C38: {=IFERROR(IF(SUMPRODUCT(ABS('LTM Waterfall'!D10:AB15))<=0.000001,1,0),1)} -> 0 | D38: =IF(ABS(C38)>0.01,"Fail",IF(OR(E38="",E38>0.000001),"Pass",IF(AND(E38=0,C38=0),"Pass (No Data)","No Data"))) -> Pass | E38: {=SUMPRODUCT(ABS('LTM Waterfall'!D10:AB15))} -> 12008907
A39: LTMWaterfall | B39: Data Presence - Customer Count | C39: {=IFERROR(IF(SUMPRODUCT(ABS('LTM Waterfall'!D48:AB51))<=0.000001,1,0),1)} -> 0 | D39: =IF(ABS(C39)>0.01,"Fail",IF(OR(E39="",E39>0.000001),"Pass",IF(AND(E39=0,C39=0),"Pass (No Data)","No Data"))) -> Pass | E39: {=SUMPRODUCT(ABS('LTM Waterfall'!D48:AB51))} -> 4282
A40: LTMWaterfall | B40: Source Connectivity | C40: =0 -> 0 | D40: =IF(ABS(C40)>0.01,"Fail",IF(OR(E40="",E40>0.000001),"Pass",IF(AND(E40=0,C40=0),"Pass (No Data)","No Data"))) -> Pass | E40: =""
...

Sheet Waterfalls >

Sheet Annual Waterfall
C5: Annual Waterfall
C6: ="("&ToC!$E$12&" "&ToC!$E$11&")" -> ($ Actuals)
C8: Annual Waterfall | D8: 44926 | E8: 45291 | F8: 45657 | G8: 46022
C10: BoP ARR | E10: =+D15 -> 216022.8 | F10: =+E15 -> 214713.6 | G10: =+F15 -> 223283.88
A11: NEW | C11: New | E11: =+SUMIFS('Quikirr Data'!EW$4:EW$103,'Quikirr Data'!EW$4:EW$103,"<>"&0)*ToC!$E$15/ToC!$E$10 -> 14969.76 | F11: =+SUMIFS('Quikirr Data'!EX$4:EX$103,'Quikirr Data'!EX$4:EX$103,"<>"&0)*ToC!$E$15/ToC!$E$10 -> 12625.2 | G11: =+SUMIFS('Quikirr Data'!EY$4:EY$103,'Quikirr Data'!EY$4:EY$103,"<>"&0)*ToC!$E$15/ToC!$E$10 -> 23635.68
A12: UPSELL | C12: Upsell | E12: =+SUMIFS('Quikirr Data'!FL$4:FL$103,'Quikirr Data'!FL$4:FL$103,"<>"&0)*ToC!$E$15/ToC!$E$10 -> 4359.72 | F12: =+SUMIFS('Quikirr Data'!FM$4:FM$103,'Quikirr Data'!FM$4:FM$103,"<>"&0)*ToC!$E$15/ToC!$E$10 -> 4117.68 | G12: =+SUMIFS('Quikirr Data'!FN$4:FN$103,'Quikirr Data'!FN$4:FN$103,"<>"&0)*ToC!$E$15/ToC!$E$10 -> 5916.12
A13: DOWNSELL | C13: (Downsell) | E13: =+SUMIFS('Quikirr Data'!FG$4:FG$103,'Quikirr Data'!FG$4:FG$103,"<>"&0)*ToC!$E$15/ToC!$E$10 -> -4758.72 | F13: =+SUMIFS('Quikirr Data'!FH$4:FH$103,'Quikirr Data'!FH$4:FH$103,"<>"&0)*ToC!$E$15/ToC!$E$10 -> -552.6 | G13: =+SUMIFS('Quikirr Data'!FI$4:FI$103,'Quikirr Data'!FI$4:FI$103,"<>"&0)*ToC!$E$15/ToC!$E$10 -> -3482.28
A14: CHURN | C14: (Churn) | E14: =+SUMIFS('Quikirr Data'!FB$4:FB$103,'Quikirr Data'!FB$4:FB$103,"<>"&0)*ToC!$E$15/ToC!$E$10 -> -15879.96 | F14: =+SUMIFS('Quikirr Data'!FC$4:FC$103,'Quikirr Data'!FC$4:FC$103,"<>"&0)*ToC!$E$15/ToC!$E$10 -> -7620 | G14: =+SUMIFS('Quikirr Data'!FD$4:FD$103,'Quikirr Data'!FD$4:FD$103,"<>"&0)*ToC!$E$15/ToC!$E$10 -> -4536
C15: EoP ARR | D15: =+SUMIFS('Quikirr Data'!C$4:C$103,'Quikirr Data'!C$4:C$103,"<>"&0)*ToC!$E$15/ToC!$E$10 -> 216022.8 | E15: =+SUM(E10:E14) -> 214713.6 | F15: =+SUM(F10:F14) -> 223283.88 | G15: =+SUM(G10:G14) -> 244817.4
C17: New % of BoP | E17: =+IFERROR(E11/E10,0) -> 0.06929713 | F17: =+IFERROR(F11/F10,0) -> 0.058800188 | G17: =+IFERROR(G11/G10,0) -> 0.10585484
C18: Upsell % of BoP | E18: =+IFERROR(E12/E10,0) -> 0.020181759 | F18: =+IFERROR(F12/F10,0) -> 0.019177546 | G18: =+IFERROR(G12/G10,0) -> 0.026495957
C19: (Downsell) % of BoP | E19: =+IFERROR(E13/E10,0) -> -0.022028786 | F19: =+IFERROR(F13/F10,0) -> -0.0025736609 | G19: =+IFERROR(G13/G10,0) -> -0.015595752
C20: (Churn) % of BoP | E20: =+IFERROR(E14/E10,0) -> -0.073510574 | F20: =+IFERROR(F14/F10,0) -> -0.035489135 | G20: =+IFERROR(G14/G10,0) -> -0.020314946
C21: Gross Adds % of BoP | E21: =+IFERROR((SUM(E11:E12))/E10,0) -> 0.089478888 | F21: =+IFERROR((SUM(F11:F12))/F10,0) -> 0.077977734 | G21: =+IFERROR((SUM(G11:G12))/G10,0) -> 0.1323508
C22: Gross Losses % of BoP | E22: =+IFERROR((SUM(E13:E14))/E10,0) -> -0.09553936 | F22: =+IFERROR((SUM(F13:F14))/F10,0) -> -0.038062796 | G22: =+IFERROR((SUM(G13:G14))/G10,0) -> -0.035910698
C24: New % of Average | E24: =+IFERROR(E11/AVERAGE(E10,E15),0) -> 0.069507755 | F24: =+IFERROR(F11/AVERAGE(F10,F15),0) -> 0.057649647 | G24: =+IFERROR(G11/AVERAGE(G10,G15),0) -> 0.10098533
C25: Upsell % of Average | E25: =+IFERROR(E12/AVERAGE(E10,E15),0) -> 0.0202431 | F25: =+IFERROR(F12/AVERAGE(F10,F15),0) -> 0.0188023 | G25: =+IFERROR(G12/AVERAGE(G10,G15),0) -> 0.025277094
C26: (Downsell) % of Average | E26: =+IFERROR(E13/AVERAGE(E10,E15),0) -> -0.022095741 | F26: =+IFERROR(F13/AVERAGE(F10,F15),0) -> -0.0025233022 | G26: =+IFERROR(G13/AVERAGE(G10,G15),0) -> -0.014878319
C27: (Churn) % of Average | E27: =+IFERROR(E14/AVERAGE(E10,E15),0) -> -0.073734005 | F27: =+IFERROR(F14/AVERAGE(F10,F15),0) -> -0.034794721 | G27: =+IFERROR(G14/AVERAGE(G10,G15),0) -> -0.019380421
C28: Gross Adds % of Average | E28: =+IFERROR((SUM(E11:E12))/AVERAGE(E10,E15),0) -> 0.089750855 | F28: =+IFERROR((SUM(F11:F12))/AVERAGE(F10,F15),0) -> 0.076451947 | G28: =+IFERROR((SUM(G11:G12))/AVERAGE(G10,G15),0) -> 0.12626242
C29: Gross Losses % of Average | E29: =+IFERROR((SUM(E13:E14))/AVERAGE(E10,E15),0) -> -0.095829746 | F29: =+IFERROR((SUM(F13:F14))/AVERAGE(F10,F15),0) -> -0.037318023 | G29: =+IFERROR((SUM(G13:G14))/AVERAGE(G10,G15),0) -> -0.03425874
C31: % Growth New (YoY) | F31: =+IFERROR(F11/E11-1,0) -> -0.15661975 | G31: =+IFERROR(G11/F11-1,0) -> 0.87210341
C32: % Growth Upsell (YoY) | F32: =+IFERROR(F12/E12-1,0) -> -0.055517327 | G32: =+IFERROR(G12/F12-1,0) -> 0.43676051
C33: % Growth New + Upsell (YoY) | F33: =+IFERROR(F39/E39-1,0) -> -0.13381633 | G33: =+IFERROR(G39/F39-1,0) -> 0.76503684
C34: % Growth Churn (YoY) | F34: =+IFERROR(F14/E14-1,0) -> -0.52014992 | G34: =+IFERROR(G14/F14-1,0) -> -0.40472441
C35: % Growth Downsell + Churn (YoY) | F35: =+IFERROR(F40/E40-1,0) -> -0.60401537 | G35: =+IFERROR(G40/F40-1,0) -> -0.018882608
C37: % Growth | E37: =+IFERROR(E15/E10-1,0) -> -0.0060604714 | F37: =+IFERROR(F15/F10-1,0) -> 0.039914938 | G37: =+IFERROR(G15/G10-1,0) -> 0.096440101
C38: Net New ARR | E38: =+E15-E10 -> -1309.2 | F38: =+F15-F10 -> 8570.28 | G38: =+G15-G10 -> 21533.52
C39: New + Upsell | E39: =+SUM(E11:E12) -> 19329.48 | F39: =+SUM(F11:F12) -> 16742.88 | G39: =+SUM(G11:G12) -> 29551.8
C40: Downsell + Churn | E40: =+SUM(E13:E14) -> -20638.68 | F40: =+SUM(F13:F14) -> -8172.6 | G40: =+SUM(G13:G14) -> -8018.28
C42: Gross Retention % | E42: =+IFERROR((SUM(E10,E13:E14)/E10),0) -> 0.90446064 | F42: =+IFERROR((SUM(F10,F13:F14)/F10),0) -> 0.9619372 | G42: =+IFERROR((SUM(G10,G13:G14)/G10),0) -> 0.9640893
C43: Loss-Only Retention % | E43: =+IFERROR((SUM(E10,E14)/E10),0) -> 0.92648943 | F43: =+IFERROR((SUM(F10,F14)/F10),0) -> 0.96451086 | G43: =+IFERROR((SUM(G10,G14)/G10),0) -> 0.97968505
C44: Net Retention % | E44: =+IFERROR((SUM(E10,E12:E14)/E10),0) -> 0.9246424 | F44: =+IFERROR((SUM(F10,F12:F14)/F10),0) -> 0.98111475 | G44: =+IFERROR((SUM(G10,G12:G14)/G10),0) -> 0.99058526
C46: Customer Waterfall
C48: BoP Customers | E48: =+D51 -> 79 | F48: =+E51 -> 79 | G48: =+F51 -> 80
A49: NEW | C49: New | E49: =+COUNTIFS('Quikirr Data'!EW$4:EW$103,">"&0) -> 6 | F49: =+COUNTIFS('Quikirr Data'!EX$4:EX$103,">"&0) -> 5 | G49: =+COUNTIFS('Quikirr Data'!EY$4:EY$103,">"&0) -> 7
A50: CHURN | C50: (Churn) | E50: =+COUNTIFS('Quikirr Data'!FB$4:FB$103,"<"&0)*-1 -> -6 | F50: =+COUNTIFS('Quikirr Data'!FC$4:FC$103,"<"&0)*-1 -> -4 | G50: =+COUNTIFS('Quikirr Data'!FD$4:FD$103,"<"&0)*-1 -> -2
C51: EoP Customers | D51: =+COUNTIFS('Quikirr Data'!C$4:C$103,">"&0) -> 79 | E51: =+SUM(E48:E50) -> 79 | F51: =+SUM(F48:F50) -> 80 | G51: =+SUM(G48:G50) -> 85
C53: Net Logos Added | E53: =+SUM(E49:E50) -> 0 | F53: =+SUM(F49:F50) -> 1 | G53: =+SUM(G49:G50) -> 5
C54: Logo % Growth | E54: =+IFERROR(E51/E48-1,0) -> 0 | F54: =+IFERROR(F51/F48-1,0) -> 0.012658228 | G54: =+IFERROR(G51/G48-1,0) -> 0.0625
...

Sheet Quarterly Waterfall
C5: Quarterly Waterfall
C6: ="("&ToC!$E$12&" "&ToC!$E$11&")" -> ($ Actuals)
C8: Quarterly Waterfall | D8: 44926 | E8: 45016 | F8: 45107 | G8: 45199 | H8: 45291 | I8: 45382 | J8: 45473 | K8: 45565 | L8: 45657 | M8: 45747 | N8: 45838 | O8: 45930 | P8: 46022
C10: BoP ARR | E10: =+D15 -> 216022.8 | F10: =+E15 -> 229915.2 | G10: =+F15 -> 229781.64 | H10: =+G15 -> 218279.04 | I10: =+H15 -> 214713.6 | J10: =+I15 -> 213660.6 | K10: =+J15 -> 212321.4 | L10: =+K15 -> 221747.76 | ... P10: =+O15 -> 244739.64
A11: NEW | C11: New | E11: =+SUMIFS('Quikirr Data'!BT$4:BT$103,'Quikirr Data'!BT$4:BT$103,"<>"&0)*ToC!$E$15/ToC!$E$10 -> 15627.96 | F11: =+SUMIFS('Quikirr Data'!BU$4:BU$103,'Quikirr Data'!BU$4:BU$103,"<>"&0)*ToC!$E$15/ToC!$E$10 -> 0 | G11: =+SUMIFS('Quikirr Data'!BV$4:BV$103,'Quikirr Data'!BV$4:BV$103,"<>"&0)*ToC!$E$15/ToC!$E$10 -> 0 | H11: =+SUMIFS('Quikirr Data'!BW$4:BW$103,'Quikirr Data'!BW$4:BW$103,"<>"&0)*ToC!$E$15/ToC!$E$10 -> 0 | I11: =+SUMIFS('Quikirr Data'!BX$4:BX$103,'Quikirr Data'!BX$4:BX$103,"<>"&0)*ToC!$E$15/ToC!$E$10 -> 0 | J11: =+SUMIFS('Quikirr Data'!BY$4:BY$103,'Quikirr Data'!BY$4:BY$103,"<>"&0)*ToC!$E$15/ToC!$E$10 -> 0 | K11: =+SUMIFS('Quikirr Data'!BZ$4:BZ$103,'Quikirr Data'!BZ$4:BZ$103,"<>"&0)*ToC!$E$15/ToC!$E$10 -> 12625.2 | L11: =+SUMIFS('Quikirr Data'!CA$4:CA$103,'Quikirr Data'!CA$4:CA$103,"<>"&0)*ToC!$E$15/ToC!$E$10 -> 0 | ... P11: =+SUMIFS('Quikirr Data'!CE$4:CE$103,'Quikirr Data'!CE$4:CE$103,"<>"&0)*ToC!$E$15/ToC!$E$10 -> 0
A12: UPSELL | C12: Upsell | E12: =+SUMIFS('Quikirr Data'!DJ$4:DJ$103,'Quikirr Data'!DJ$4:DJ$103,"<>"&0)*ToC!$E$15/ToC!$E$10 -> 533.16 | F12: =+SUMIFS('Quikirr Data'!DK$4:DK$103,'Quikirr Data'!DK$4:DK$103,"<>"&0)*ToC!$E$15/ToC!$E$10 -> 1554.72 | G12: =+SUMIFS('Quikirr Data'!DL$4:DL$103,'Quikirr Data'!DL$4:DL$103,"<>"&0)*ToC!$E$15/ToC!$E$10 -> 3291.96 | H12: =+SUMIFS('Quikirr Data'!DM$4:DM$103,'Quikirr Data'!DM$4:DM$103,"<>"&0)*ToC!$E$15/ToC!$E$10 -> 1100.28 | I12: =+SUMIFS('Quikirr Data'!DN$4:DN$103,'Quikirr Data'!DN$4:DN$103,"<>"&0)*ToC!$E$15/ToC!$E$10 -> 2151 | J12: =+SUMIFS('Quikirr Data'!DO$4:DO$103,'Quikirr Data'!DO$4:DO$103,"<>"&0)*ToC!$E$15/ToC!$E$10 -> 208.8 | K12: =+SUMIFS('Quikirr Data'!DP$4:DP$103,'Quikirr Data'!DP$4:DP$103,"<>"&0)*ToC!$E$15/ToC!$E$10 -> 328.56 | L12: =+SUMIFS('Quikirr Data'!DQ$4:DQ$103,'Quikirr Data'!DQ$4:DQ$103,"<>"&0)*ToC!$E$15/ToC!$E$10 -> 1536.12 | ... P12: =+SUMIFS('Quikirr Data'!DU$4:DU$103,'Quikirr Data'!DU$4:DU$103,"<>"&0)*ToC!$E$15/ToC!$E$10 -> 77.76
A13: DOWNSELL | C13: (Downsell) | E13: =+SUMIFS('Quikirr Data'!CV$4:CV$103,'Quikirr Data'!CV$4:CV$103,"<>"&0)*ToC!$E$15/ToC!$E$10 -> -2268.72 | F13: =+SUMIFS('Quikirr Data'!CW$4:CW$103,'Quikirr Data'!CW$4:CW$103,"<>"&0)*ToC!$E$15/ToC!$E$10 -> -1688.28 | G13: =+SUMIFS('Quikirr Data'!CX$4:CX$103,'Quikirr Data'!CX$4:CX$103,"<>"&0)*ToC!$E$15/ToC!$E$10 -> -2361.48 | H13: =+SUMIFS('Quikirr Data'!CY$4:CY$103,'Quikirr Data'!CY$4:CY$103,"<>"&0)*ToC!$E$15/ToC!$E$10 -> -489.72 | I13: =+SUMIFS('Quikirr Data'!CZ$4:CZ$103,'Quikirr Data'!CZ$4:CZ$103,"<>"&0)*ToC!$E$15/ToC!$E$10 -> -480 | J13: =+SUMIFS('Quikirr Data'!DA$4:DA$103,'Quikirr Data'!DA$4:DA$103,"<>"&0)*ToC!$E$15/ToC!$E$10 -> 0 | K13: =+SUMIFS('Quikirr Data'!DB$4:DB$103,'Quikirr Data'!DB$4:DB$103,"<>"&0)*ToC!$E$15/ToC!$E$10 -> -179.4 | L13: =+SUMIFS('Quikirr Data'!DC$4:DC$103,'Quikirr Data'!DC$4:DC$103,"<>"&0)*ToC!$E$15/ToC!$E$10 -> 0 | ... P13: =+SUMIFS('Quikirr Data'!DG$4:DG$103,'Quikirr Data'!DG$4:DG$103,"<>"&0)*ToC!$E$15/ToC!$E$10 -> 0
A14: CHURN | C14: (Churn) | E14: =+SUMIFS('Quikirr Data'!CH$4:CH$103,'Quikirr Data'!CH$4:CH$103,"<>"&0)*ToC!$E$15/ToC!$E$10 -> 0 | F14: =+SUMIFS('Quikirr Data'!CI$4:CI$103,'Quikirr Data'!CI$4:CI$103,"<>"&0)*ToC!$E$15/ToC!$E$10 -> 0 | G14: =+SUMIFS('Quikirr Data'!CJ$4:CJ$103,'Quikirr Data'!CJ$4:CJ$103,"<>"&0)*ToC!$E$15/ToC!$E$10 -> -12433.08 | H14: =+SUMIFS('Quikirr Data'!CK$4:CK$103,'Quikirr Data'!CK$4:CK$103,"<>"&0)*ToC!$E$15/ToC!$E$10 -> -4176 | I14: =+SUMIFS('Quikirr Data'!CL$4:CL$103,'Quikirr Data'!CL$4:CL$103,"<>"&0)*ToC!$E$15/ToC!$E$10 -> -2724 | J14: =+SUMIFS('Quikirr Data'!CM$4:CM$103,'Quikirr Data'!CM$4:CM$103,"<>"&0)*ToC!$E$15/ToC!$E$10 -> -1548 | K14: =+SUMIFS('Quikirr Data'!CN$4:CN$103,'Quikirr Data'!CN$4:CN$103,"<>"&0)*ToC!$E$15/ToC!$E$10 -> -3348 | L14: =+SUMIFS('Quikirr Data'!CO$4:CO$103,'Quikirr Data'!CO$4:CO$103,"<>"&0)*ToC!$E$15/ToC!$E$10 -> 0 | ... P14: =+SUMIFS('Quikirr Data'!CS$4:CS$103,'Quikirr Data'!CS$4:CS$103,"<>"&0)*ToC!$E$15/ToC!$E$10 -> 0
C15: EoP ARR | D15: =+SUMIFS('Quikirr Data'!C$4:C$103,'Quikirr Data'!C$4:C$103,"<>"&0)*ToC!$E$15/ToC!$E$10 -> 216022.8 | E15: =+SUM(E10:E14) -> 229915.2 | F15: =+SUM(F10:F14) -> 229781.64 | G15: =+SUM(G10:G14) -> 218279.04 | H15: =+SUM(H10:H14) -> 214713.6 | I15: =+SUM(I10:I14) -> 213660.6 | J15: =+SUM(J10:J14) -> 212321.4 | K15: =+SUM(K10:K14) -> 221747.76 | L15: =+SUM(L10:L14) -> 223283.88 | ... P15: =+SUM(P10:P14) -> 244817.4
C17: New % of BoP | E17: =+IFERROR(E11/E10,0) -> 0.07234403 | F17: =+IFERROR(F11/F10,0) -> 0 | G17: =+IFERROR(G11/G10,0) -> 0 | H17: =+IFERROR(H11/H10,0) -> 0 | I17: =+IFERROR(I11/I10,0) -> 0 | J17: =+IFERROR(J11/J10,0) -> 0 | K17: =+IFERROR(K11/K10,0) -> 0.059462683 | L17: =+IFERROR(L11/L10,0) -> 0 | ... P17: =+IFERROR(P11/P10,0) -> 0
C18: Upsell % of BoP | E18: =+IFERROR(E12/E10,0) -> 0.0024680728 | F18: =+IFERROR(F12/F10,0) -> 0.0067621453 | G18: =+IFERROR(G12/G10,0) -> 0.014326471 | H18: =+IFERROR(H12/H10,0) -> 0.0050407039 | I18: =+IFERROR(I12/I10,0) -> 0.010017996 | J18: =+IFERROR(J12/J10,0) -> 0.00097725084 | K18: =+IFERROR(K12/K10,0) -> 0.0015474653 | L18: =+IFERROR(L12/L10,0) -> 0.0069273304 | ... P18: =+IFERROR(P12/P10,0) -> 0.0003177254
C19: (Downsell) % of BoP | E19: =+IFERROR(E13/E10,0) -> -0.010502225 | F19: =+IFERROR(F13/F10,0) -> -0.0073430552 | G19: =+IFERROR(G13/G10,0) -> -0.010277061 | H19: =+IFERROR(H13/H10,0) -> -0.0022435503 | I19: =+IFERROR(I13/I10,0) -> -0.0022355361 | J19: =+IFERROR(J13/J10,0) -> 0 | K19: =+IFERROR(K13/K10,0) -> -0.00084494545 | L19: =+IFERROR(L13/L10,0) -> 0 | ... P19: =+IFERROR(P13/P10,0) -> 0
C20: (Churn) % of BoP | E20: =+IFERROR(E14/E10,0) -> 0 | F20: =+IFERROR(F14/F10,0) -> 0 | G20: =+IFERROR(G14/G10,0) -> -0.054108239 | H20: =+IFERROR(H14/H10,0) -> -0.019131475 | I20: =+IFERROR(I14/I10,0) -> -0.012686667 | J20: =+IFERROR(J14/J10,0) -> -0.0072451355 | K20: =+IFERROR(K14/K10,0) -> -0.015768547 | L20: =+IFERROR(L14/L10,0) -> 0 | ... P20: =+IFERROR(P14/P10,0) -> 0
C21: Gross Adds % of BoP | E21: =+IFERROR((SUM(E11:E12))/E10,0) -> 0.074812103 | F21: =+IFERROR((SUM(F11:F12))/F10,0) -> 0.0067621453 | G21: =+IFERROR((SUM(G11:G12))/G10,0) -> 0.014326471 | H21: =+IFERROR((SUM(H11:H12))/H10,0) -> 0.0050407039 | I21: =+IFERROR((SUM(I11:I12))/I10,0) -> 0.010017996 | J21: =+IFERROR((SUM(J11:J12))/J10,0) -> 0.00097725084 | K21: =+IFERROR((SUM(K11:K12))/K10,0) -> 0.061010148 | L21: =+IFERROR((SUM(L11:L12))/L10,0) -> 0.0069273304 | ... P21: =+IFERROR((SUM(P11:P12))/P10,0) -> 0.0003177254
C22: Gross Losses % of BoP | E22: =+IFERROR((SUM(E13:E14))/E10,0) -> -0.010502225 | F22: =+IFERROR((SUM(F13:F14))/F10,0) -> -0.0073430552 | G22: =+IFERROR((SUM(G13:G14))/G10,0) -> -0.064385301 | H22: =+IFERROR((SUM(H13:H14))/H10,0) -> -0.021375025 | I22: =+IFERROR((SUM(I13:I14))/I10,0) -> -0.014922203 | J22: =+IFERROR((SUM(J13:J14))/J10,0) -> -0.0072451355 | K22: =+IFERROR((SUM(K13:K14))/K10,0) -> -0.016613493 | L22: =+IFERROR((SUM(L13:L14))/L10,0) -> 0 | ... P22: =+IFERROR((SUM(P13:P14))/P10,0) -> 0
C24: New % of Average | E24: =+IFERROR(E11/AVERAGE(E10,E15),0) -> 0.070090282 | F24: =+IFERROR(F11/AVERAGE(F10,F15),0) -> 0 | G24: =+IFERROR(G11/AVERAGE(G10,G15),0) -> 0 | H24: =+IFERROR(H11/AVERAGE(H10,H15),0) -> 0 | I24: =+IFERROR(I11/AVERAGE(I10,I15),0) -> 0 | J24: =+IFERROR(J11/AVERAGE(J10,J15),0) -> 0 | K24: =+IFERROR(K11/AVERAGE(K10,K15),0) -> 0.058171375 | L24: =+IFERROR(L11/AVERAGE(L10,L15),0) -> 0 | ... P24: =+IFERROR(P11/AVERAGE(P10,P15),0) -> 0
C25: Upsell % of Average | E25: =+IFERROR(E12/AVERAGE(E10,E15),0) -> 0.0023911844 | F25: =+IFERROR(F12/AVERAGE(F10,F15),0) -> 0.00676411 | G25: =+IFERROR(G12/AVERAGE(G10,G15),0) -> 0.01469426 | H25: =+IFERROR(H12/AVERAGE(H10,H15),0) -> 0.0050822111 | I25: =+IFERROR(I12/AVERAGE(I10,I15),0) -> 0.010042622 | J25: =+IFERROR(J12/AVERAGE(J10,J15),0) -> 0.00098032311 | K25: =+IFERROR(K12/AVERAGE(K10,K15),0) -> 0.0015138601 | L25: =+IFERROR(L12/AVERAGE(L10,L15),0) -> 0.0069034193 | ... P25: =+IFERROR(P12/AVERAGE(P10,P15),0) -> 0.00031767493
C26: (Downsell) % of Average | E26: =+IFERROR(E13/AVERAGE(E10,E15),0) -> -0.010175047 | F26: =+IFERROR(F13/AVERAGE(F10,F15),0) -> -0.0073451886 | G26: =+IFERROR(G13/AVERAGE(G10,G15),0) -> -0.010540894 | H26: =+IFERROR(H13/AVERAGE(H10,H15),0) -> -0.0022620246 | I26: =+IFERROR(I13/AVERAGE(I10,I15),0) -> -0.0022410313 | J26: =+IFERROR(J13/AVERAGE(J10,J15),0) -> 0 | K26: =+IFERROR(K13/AVERAGE(K10,K15),0) -> -0.00082659639 | L26: =+IFERROR(L13/AVERAGE(L10,L15),0) -> 0 | ... P26: =+IFERROR(P13/AVERAGE(P10,P15),0) -> 0
C27: (Churn) % of Average | E27: =+IFERROR(E14/AVERAGE(E10,E15),0) -> 0 | F27: =+IFERROR(F14/AVERAGE(F10,F15),0) -> 0 | G27: =+IFERROR(G14/AVERAGE(G10,G15),0) -> -0.055497305 | H27: =+IFERROR(H14/AVERAGE(H10,H15),0) -> -0.019289011 | I27: =+IFERROR(I14/AVERAGE(I10,I15),0) -> -0.012717853 | J27: =+IFERROR(J14/AVERAGE(J10,J15),0) -> -0.0072679127 | K27: =+IFERROR(K14/AVERAGE(K10,K15),0) -> -0.015426113 | L27: =+IFERROR(L14/AVERAGE(L10,L15),0) -> 0 | ... P27: =+IFERROR(P14/AVERAGE(P10,P15),0) -> 0
C28: Gross Adds % of Average | E28: =+IFERROR((SUM(E11:E12))/AVERAGE(E10,E15),0) -> 0.072481466 | F28: =+IFERROR((SUM(F11:F12))/AVERAGE(F10,F15),0) -> 0.00676411 | G28: =+IFERROR((SUM(G11:G12))/AVERAGE(G10,G15),0) -> 0.01469426 | H28: =+IFERROR((SUM(H11:H12))/AVERAGE(H10,H15),0) -> 0.0050822111 | I28: =+IFERROR((SUM(I11:I12))/AVERAGE(I10,I15),0) -> 0.010042622 | J28: =+IFERROR((SUM(J11:J12))/AVERAGE(J10,J15),0) -> 0.00098032311 | K28: =+IFERROR((SUM(K11:K12))/AVERAGE(K10,K15),0) -> 0.059685235 | L28: =+IFERROR((SUM(L11:L12))/AVERAGE(L10,L15),0) -> 0.0069034193 | ... P28: =+IFERROR((SUM(P11:P12))/AVERAGE(P10,P15),0) -> 0.00031767493
C29: Gross Losses % of Average | E29: =+IFERROR((SUM(E13:E14))/AVERAGE(E10,E15),0) -> -0.010175047 | F29: =+IFERROR((SUM(F13:F14))/AVERAGE(F10,F15),0) -> -0.0073451886 | G29: =+IFERROR((SUM(G13:G14))/AVERAGE(G10,G15),0) -> -0.066038198 | H29: =+IFERROR((SUM(H13:H14))/AVERAGE(H10,H15),0) -> -0.021551036 | I29: =+IFERROR((SUM(I13:I14))/AVERAGE(I10,I15),0) -> -0.014958884 | J29: =+IFERROR((SUM(J13:J14))/AVERAGE(J10,J15),0) -> -0.0072679127 | K29: =+IFERROR((SUM(K13:K14))/AVERAGE(K10,K15),0) -> -0.01625271 | L29: =+IFERROR((SUM(L13:L14))/AVERAGE(L10,L15),0) -> 0 | ... P29: =+IFERROR((SUM(P13:P14))/AVERAGE(P10,P15),0) -> 0
C31: % Growth New (QoQ) | E31: =+IFERROR(E11/D11-1,0) -> 0 | F31: =+IFERROR(F11/E11-1,0) -> -1 | G31: =+IFERROR(G11/F11-1,0) -> 0 | H31: =+IFERROR(H11/G11-1,0) -> 0 | I31: =+IFERROR(I11/H11-1,0) -> 0 | J31: =+IFERROR(J11/I11-1,0) -> 0 | K31: =+IFERROR(K11/J11-1,0) -> 0 | L31: =+IFERROR(L11/K11-1,0) -> -1 | ... P31: =+IFERROR(P11/O11-1,0) -> 0
C32: % Growth New (YoY) | I32: =+IFERROR(I11/E11-1,0) -> -1 | J32: =+IFERROR(J11/F11-1,0) -> 0 | K32: =+IFERROR(K11/G11-1,0) -> 0 | L32: =+IFERROR(L11/H11-1,0) -> 0 | M32: =+IFERROR(M11/I11-1,0) -> 0 | N32: =+IFERROR(N11/J11-1,0) -> 0 | O32: =+IFERROR(O11/K11-1,0) -> -1 | P32: =+IFERROR(P11/L11-1,0) -> 0
C33: % Growth Upsell (QoQ) | E33: =+IFERROR(E12/D12-1,0) -> 0 | F33: =+IFERROR(F12/E12-1,0) -> 1.9160477 | G33: =+IFERROR(G12/F12-1,0) -> 1.1173973 | H33: =+IFERROR(H12/G12-1,0) -> -0.66576751 | I33: =+IFERROR(I12/H12-1,0) -> 0.95495692 | J33: =+IFERROR(J12/I12-1,0) -> -0.90292887 | K33: =+IFERROR(K12/J12-1,0) -> 0.57356322 | L33: =+IFERROR(L12/K12-1,0) -> 3.6753104 | ... P33: =+IFERROR(P12/O12-1,0) -> -0.93395842
C34: % Growth Upsell (YoY) | I34: =+IFERROR(I12/E12-1,0) -> 3.0344362 | J34: =+IFERROR(J12/F12-1,0) -> -0.86569929 | K34: =+IFERROR(K12/G12-1,0) -> -0.9001932 | L34: =+IFERROR(L12/H12-1,0) -> 0.39611735 | M34: =+IFERROR(M12/I12-1,0) -> 0.42119944 | N34: =+IFERROR(N12/J12-1,0) -> 7.9356322 | O34: =+IFERROR(O12/K12-1,0) -> 2.5836377 | P34: =+IFERROR(P12/L12-1,0) -> -0.94937895
C35: % Growth New + Upsell (QoQ) | E35: =+IFERROR(E46/D46-1,0) -> 0 | F35: =+IFERROR(F46/E46-1,0) -> -0.90379875 | G35: =+IFERROR(G46/F46-1,0) -> 1.1173973 | H35: =+IFERROR(H46/G46-1,0) -> -0.66576751 | I35: =+IFERROR(I46/H46-1,0) -> 0.95495692 | J35: =+IFERROR(J46/I46-1,0) -> -0.90292887 | K35: =+IFERROR(K46/J46-1,0) -> 61.03908 | L35: =+IFERROR(L46/K46-1,0) -> -0.88141513 | ... P35: =+IFERROR(P46/O46-1,0) -> -0.93395842
C36: % Growth New + Upsell (YoY) | I36: =+IFERROR(I46/E46-1,0) -> -0.86690279 | J36: =+IFERROR(J46/F46-1,0) -> -0.86569929 | K36: =+IFERROR(K46/G46-1,0) -> 2.9349688 | L36: =+IFERROR(L46/H46-1,0) -> 0.39611735 | M36: =+IFERROR(M46/I46-1,0) -> 0.42119944 | N36: =+IFERROR(N46/J46-1,0) -> 121.13333 | O36: =+IFERROR(O46/K46-1,0) -> -0.90910438 | P36: =+IFERROR(P46/L46-1,0) -> -0.94937895
C37: % Growth Churn (QoQ) | E37: =+IFERROR(E14/D14-1,0) -> 0 | F37: =+IFERROR(F14/E14-1,0) -> 0 | G37: =+IFERROR(G14/F14-1,0) -> 0 | H37: =+IFERROR(H14/G14-1,0) -> -0.66412184 | I37: =+IFERROR(I14/H14-1,0) -> -0.34770115 | J37: =+IFERROR(J14/I14-1,0) -> -0.43171806 | K37: =+IFERROR(K14/J14-1,0) -> 1.1627907 | L37: =+IFERROR(L14/K14-1,0) -> -1 | ... P37: =+IFERROR(P14/O14-1,0) -> 0
C38: % Growth Churn (YoY) | I38: =+IFERROR(I14/E14-1,0) -> 0 | J38: =+IFERROR(J14/F14-1,0) -> 0 | K38: =+IFERROR(K14/G14-1,0) -> -0.73071837 | L38: =+IFERROR(L14/H14-1,0) -> -1 | M38: =+IFERROR(M14/I14-1,0) -> 0.66519824 | N38: =+IFERROR(N14/J14-1,0) -> -1 | O38: =+IFERROR(O14/K14-1,0) -> -1 | P38: =+IFERROR(P14/L14-1,0) -> 0
C39: % Growth Downsell + Churn (QoQ) | E39: =+IFERROR(E47/D47-1,0) -> 0 | F39: =+IFERROR(F47/E47-1,0) -> -0.25584471 | G39: =+IFERROR(G47/F47-1,0) -> 7.7630962 | H39: =+IFERROR(H47/G47-1,0) -> -0.68463273 | I39: =+IFERROR(I47/H47-1,0) -> -0.31328927 | J39: =+IFERROR(J47/I47-1,0) -> -0.51685393 | K39: =+IFERROR(K47/J47-1,0) -> 1.2786822 | L39: =+IFERROR(L47/K47-1,0) -> -1 | ... P39: =+IFERROR(P47/O47-1,0) -> 0
C40: % Growth Downsell + Churn (YoY) | I40: =+IFERROR(I47/E47-1,0) -> 0.41225008 | J40: =+IFERROR(J47/F47-1,0) -> -0.083090483 | K40: =+IFERROR(K47/G47-1,0) -> -0.76157452 | L40: =+IFERROR(L47/H47-1,0) -> -1 | M40: =+IFERROR(M47/I47-1,0) -> 1.1835206 | N40: =+IFERROR(N47/J47-1,0) -> -0.17046512 | O40: =+IFERROR(O47/K47-1,0) -> -1 | P40: =+IFERROR(P47/L47-1,0) -> 0
C42: % Growth QoQ Annualized | E42: =+IFERROR((E15/D15)^4-1,0) -> 0.28313506 | F42: =+IFERROR((F15/E15)^4-1,0) -> -0.0023216154 | G42: =+IFERROR((G15/F15)^4-1,0) -> -0.18569549 | H42: =+IFERROR((H15/G15)^4-1,0) -> -0.063753787 | I42: =+IFERROR((I15/H15)^4-1,0) -> -0.019472993 | J42: =+IFERROR((J15/I15)^4-1,0) -> -0.024836804 | K42: =+IFERROR((K15/J15)^4-1,0) -> 0.18976692 | L42: =+IFERROR((L15/K15)^4-1,0) -> 0.027998581 | ... P42: =+IFERROR((P15/O15)^4-1,0) -> 0.0012715074
C43: % Growth QoQ | E43: =+IFERROR(E15/D15-1,0) -> 0.064309878 | F43: =+IFERROR(F15/E15-1,0) -> -0.00058090983 | G43: =+IFERROR(G15/F15-1,0) -> -0.05005883 | H43: =+IFERROR(H15/G15-1,0) -> -0.016334321 | I43: =+IFERROR(I15/H15-1,0) -> -0.0049042073 | J43: =+IFERROR(J15/I15-1,0) -> -0.0062678847 | K43: =+IFERROR(K15/J15-1,0) -> 0.044396655 | L43: =+IFERROR(L15/K15-1,0) -> 0.0069273304 | ... P43: =+IFERROR(P15/O15-1,0) -> 0.0003177254
C44: % Growth YoY | H44: =+IFERROR(H15/D15-1,0) -> -0.0060604714 | I44: =+IFERROR(I15/E15-1,0) -> -0.07069824 | J44: =+IFERROR(J15/F15-1,0) -> -0.075986228 | K44: =+IFERROR(K15/G15-1,0) -> 0.015891219 | L44: =+IFERROR(L15/H15-1,0) -> 0.039914938 | M44: =+IFERROR(M15/I15-1,0) -> 0.02660425 | N44: =+IFERROR(N15/J15-1,0) -> 0.1471392 | O44: =+IFERROR(O15/K15-1,0) -> 0.10368484 | P44: =+IFERROR(P15/L15-1,0) -> 0.096440101
C45: Net New ARR QoQ | E45: =+E15-E10 -> 13892.4 | F45: =+F15-F10 -> -133.56 | G45: =+G15-G10 -> -11502.6 | H45: =+H15-H10 -> -3565.44 | I45: =+I15-I10 -> -1053 | J45: =+J15-J10 -> -1339.2 | K45: =+K15-K10 -> 9426.36 | L45: =+L15-L10 -> 1536.12 | ... P45: =+P15-P10 -> 77.76
C46: New + Upsell QoQ | E46: =+SUM(E11:E12) -> 16161.12 | F46: =+SUM(F11:F12) -> 1554.72 | G46: =+SUM(G11:G12) -> 3291.96 | H46: =+SUM(H11:H12) -> 1100.28 | I46: =+SUM(I11:I12) -> 2151 | J46: =+SUM(J11:J12) -> 208.8 | K46: =+SUM(K11:K12) -> 12953.76 | L46: =+SUM(L11:L12) -> 1536.12 | ... P46: =+SUM(P11:P12) -> 77.76
C47: Downsell + Churn QoQ | E47: =+SUM(E13:E14) -> -2268.72 | F47: =+SUM(F13:F14) -> -1688.28 | G47: =+SUM(G13:G14) -> -14794.56 | H47: =+SUM(H13:H14) -> -4665.72 | I47: =+SUM(I13:I14) -> -3204 | J47: =+SUM(J13:J14) -> -1548 | K47: =+SUM(K13:K14) -> -3527.4 | L47: =+SUM(L13:L14) -> 0 | ... P47: =+SUM(P13:P14) -> 0
C49: Gross Retention (QoQ Annualized) | E49: =+IFERROR((SUM(E10,E13:E14)/E10)^4,0) -> 0.95864826 | F49: =+IFERROR((SUM(F10,F13:F14)/F10)^4,0) -> 0.97094972 | G49: =+IFERROR((SUM(G10,G13:G14)/G10)^4,0) -> 0.76628116 | H49: =+IFERROR((SUM(H10,H13:H14)/H10)^4,0) -> 0.91720239 | I49: =+IFERROR((SUM(I10,I13:I14)/I10)^4,0) -> 0.94163398 | J49: =+IFERROR((SUM(J10,J13:J14)/J10)^4,0) -> 0.97133289 | K49: =+IFERROR((SUM(K10,K13:K14)/K10)^4,0) -> 0.93518381 | L49: =+IFERROR((SUM(L10,L13:L14)/L10)^4,0) -> 1 | ... P49: =+IFERROR((SUM(P10,P13:P14)/P10)^4,0) -> 1
C50: Loss-Only Retention (QoQ Annualized) | E50: =+IFERROR((SUM(E10,E14)/E10)^4,0) -> 1 | F50: =+IFERROR((SUM(F10,F14)/F10)^4,0) -> 1 | G50: =+IFERROR((SUM(G10,G14)/G10)^4,0) -> 0.80050817 | H50: =+IFERROR((SUM(H10,H14)/H10)^4,0) -> 0.9256423 | I50: =+IFERROR((SUM(I10,I14)/I10)^4,0) -> 0.9502109 | J50: =+IFERROR((SUM(J10,J14)/J10)^4,0) -> 0.97133289 | K50: =+IFERROR((SUM(K10,K14)/K10)^4,0) -> 0.93840207 | L50: =+IFERROR((SUM(L10,L14)/L10)^4,0) -> 1 | ... P50: =+IFERROR((SUM(P10,P14)/P10)^4,0) -> 1
C51: Net Retention (QoQ Annualized) | E51: =+IFERROR((SUM(E10,E12:E14)/E10)^4,0) -> 0.96824861 | F51: =+IFERROR((SUM(F10,F12:F14)/F10)^4,0) -> 0.99767838 | G51: =+IFERROR((SUM(G10,G12:G14)/G10)^4,0) -> 0.81430451 | H51: =+IFERROR((SUM(H10,H12:H14)/H10)^4,0) -> 0.93624621 | I51: =+IFERROR((SUM(I10,I12:I14)/I10)^4,0) -> 0.98052701 | J51: =+IFERROR((SUM(J10,J12:J14)/J10)^4,0) -> 0.9751632 | K51: =+IFERROR((SUM(K10,K12:K14)/K10)^4,0) -> 0.94108417 | L51: =+IFERROR((SUM(L10,L12:L14)/L10)^4,0) -> 1.0279986 | ... P51: =+IFERROR((SUM(P10,P12:P14)/P10)^4,0) -> 1.0012715
...

Sheet LTM Waterfall
C5: LTM Waterfall
C6: ="("&ToC!$E$12&" "&ToC!$E$11&")" -> ($ Actuals)
C8: LTM Waterfall | D8: 45291 | E8: 45322 | F8: 45351 | G8: 45382 | H8: 45412 | I8: 45443 | J8: 45473 | K8: 45504 | L8: 45535 | M8: 45565 | N8: 45596 | O8: 45626 | P8: 45657 | Q8: 45688 | R8: 45716 | S8: 45747 | T8: 45777 | U8: 45808 | V8: 45838 | W8: 45869 | X8: 45900 | Y8: 45930 | Z8: 45961 | AA8: 45991 | AB8: 46022
C10: BoP ARR | D10: =+SUMIFS('Quikirr Data'!C$4:C$103,'Quikirr Data'!C$4:C$103,"<>"&0)*ToC!$E$15/ToC!$E$10 -> 216022.8 | E10: =+SUMIFS('Quikirr Data'!D$4:D$103,'Quikirr Data'!D$4:D$103,"<>"&0)*ToC!$E$15/ToC!$E$10 -> 216022.8 | F10: =+SUMIFS('Quikirr Data'!E$4:E$103,'Quikirr Data'!E$4:E$103,"<>"&0)*ToC!$E$15/ToC!$E$10 -> 213975.48 | G10: =+SUMIFS('Quikirr Data'!F$4:F$103,'Quikirr Data'!F$4:F$103,"<>"&0)*ToC!$E$15/ToC!$E$10 -> 229915.2 | H10: =+SUMIFS('Quikirr Data'!G$4:G$103,'Quikirr Data'!G$4:G$103,"<>"&0)*ToC!$E$15/ToC!$E$10 -> 230063.88 | I10: =+SUMIFS('Quikirr Data'!H$4:H$103,'Quikirr Data'!H$4:H$103,"<>"&0)*ToC!$E$15/ToC!$E$10 -> 230325 | J10: =+SUMIFS('Quikirr Data'!I$4:I$103,'Quikirr Data'!I$4:I$103,"<>"&0)*ToC!$E$15/ToC!$E$10 -> 229781.64 | K10: =+SUMIFS('Quikirr Data'!J$4:J$103,'Quikirr Data'!J$4:J$103,"<>"&0)*ToC!$E$15/ToC!$E$10 -> 223671.6 | ... AB10: =+SUMIFS('Quikirr Data'!AA$4:AA$103,'Quikirr Data'!AA$4:AA$103,"<>"&0)*ToC!$E$15/ToC!$E$10 -> 223283.88
A11: NEW | C11: New | D11: =+SUMIFS('Quikirr Data'!HV$4:HV$103,'Quikirr Data'!HV$4:HV$103,"<>"&0)*ToC!$E$15/ToC!$E$10 -> 14969.76 | E11: =+SUMIFS('Quikirr Data'!HW$4:HW$103,'Quikirr Data'!HW$4:HW$103,"<>"&0)*ToC!$E$15/ToC!$E$10 -> 14969.76 | F11: =+SUMIFS('Quikirr Data'!HX$4:HX$103,'Quikirr Data'!HX$4:HX$103,"<>"&0)*ToC!$E$15/ToC!$E$10 -> 14969.76 | G11: =+SUMIFS('Quikirr Data'!HY$4:HY$103,'Quikirr Data'!HY$4:HY$103,"<>"&0)*ToC!$E$15/ToC!$E$10 -> 0 | H11: =+SUMIFS('Quikirr Data'!HZ$4:HZ$103,'Quikirr Data'!HZ$4:HZ$103,"<>"&0)*ToC!$E$15/ToC!$E$10 -> 0 | I11: =+SUMIFS('Quikirr Data'!IA$4:IA$103,'Quikirr Data'!IA$4:IA$103,"<>"&0)*ToC!$E$15/ToC!$E$10 -> 0 | J11: =+SUMIFS('Quikirr Data'!IB$4:IB$103,'Quikirr Data'!IB$4:IB$103,"<>"&0)*ToC!$E$15/ToC!$E$10 -> 0 | K11: =+SUMIFS('Quikirr Data'!IC$4:IC$103,'Quikirr Data'!IC$4:IC$103,"<>"&0)*ToC!$E$15/ToC!$E$10 -> 12625.2 | ... AB11: =+SUMIFS('Quikirr Data'!IT$4:IT$103,'Quikirr Data'!IT$4:IT$103,"<>"&0)*ToC!$E$15/ToC!$E$10 -> 23635.68
A12: UPSELL | C12: Upsell | D12: =+SUMIFS('Quikirr Data'!KV$4:KV$103,'Quikirr Data'!KV$4:KV$103,"<>"&0)*ToC!$E$15/ToC!$E$10 -> 4359.72 | E12: =+SUMIFS('Quikirr Data'!KW$4:KW$103,'Quikirr Data'!KW$4:KW$103,"<>"&0)*ToC!$E$15/ToC!$E$10 -> 6159.72 | F12: =+SUMIFS('Quikirr Data'!KX$4:KX$103,'Quikirr Data'!KX$4:KX$103,"<>"&0)*ToC!$E$15/ToC!$E$10 -> 6495.96 | G12: =+SUMIFS('Quikirr Data'!KY$4:KY$103,'Quikirr Data'!KY$4:KY$103,"<>"&0)*ToC!$E$15/ToC!$E$10 -> 6564.12 | H12: =+SUMIFS('Quikirr Data'!KZ$4:KZ$103,'Quikirr Data'!KZ$4:KZ$103,"<>"&0)*ToC!$E$15/ToC!$E$10 -> 6236.76 | I12: =+SUMIFS('Quikirr Data'!LA$4:LA$103,'Quikirr Data'!LA$4:LA$103,"<>"&0)*ToC!$E$15/ToC!$E$10 -> 6901.56 | J12: =+SUMIFS('Quikirr Data'!LB$4:LB$103,'Quikirr Data'!LB$4:LB$103,"<>"&0)*ToC!$E$15/ToC!$E$10 -> 6409.08 | K12: =+SUMIFS('Quikirr Data'!LC$4:LC$103,'Quikirr Data'!LC$4:LC$103,"<>"&0)*ToC!$E$15/ToC!$E$10 -> 6766.08 | ... AB12: =+SUMIFS('Quikirr Data'!LT$4:LT$103,'Quikirr Data'!LT$4:LT$103,"<>"&0)*ToC!$E$15/ToC!$E$10 -> 5916.12
A13: DOWNSELL | C13: (Downsell) | D13: =+SUMIFS('Quikirr Data'!JV$4:JV$103,'Quikirr Data'!JV$4:JV$103,"<>"&0)*ToC!$E$15/ToC!$E$10 -> -4758.72 | E13: =+SUMIFS('Quikirr Data'!JW$4:JW$103,'Quikirr Data'!JW$4:JW$103,"<>"&0)*ToC!$E$15/ToC!$E$10 -> -5602.2 | F13: =+SUMIFS('Quikirr Data'!JX$4:JX$103,'Quikirr Data'!JX$4:JX$103,"<>"&0)*ToC!$E$15/ToC!$E$10 -> -2685.48 | G13: =+SUMIFS('Quikirr Data'!JY$4:JY$103,'Quikirr Data'!JY$4:JY$103,"<>"&0)*ToC!$E$15/ToC!$E$10 -> -3204 | H13: =+SUMIFS('Quikirr Data'!JZ$4:JZ$103,'Quikirr Data'!JZ$4:JZ$103,"<>"&0)*ToC!$E$15/ToC!$E$10 -> -3603.84 | I13: =+SUMIFS('Quikirr Data'!KA$4:KA$103,'Quikirr Data'!KA$4:KA$103,"<>"&0)*ToC!$E$15/ToC!$E$10 -> -4136.28 | J13: =+SUMIFS('Quikirr Data'!KB$4:KB$103,'Quikirr Data'!KB$4:KB$103,"<>"&0)*ToC!$E$15/ToC!$E$10 -> -2880.72 | K13: =+SUMIFS('Quikirr Data'!KC$4:KC$103,'Quikirr Data'!KC$4:KC$103,"<>"&0)*ToC!$E$15/ToC!$E$10 -> -718.68 | ... AB13: =+SUMIFS('Quikirr Data'!KT$4:KT$103,'Quikirr Data'!KT$4:KT$103,"<>"&0)*ToC!$E$15/ToC!$E$10 -> -3482.28
A14: CHURN | C14: (Churn) | D14: =+SUMIFS('Quikirr Data'!IV$4:IV$103,'Quikirr Data'!IV$4:IV$103,"<>"&0)*ToC!$E$15/ToC!$E$10 -> -15879.96 | E14: =+SUMIFS('Quikirr Data'!IW$4:IW$103,'Quikirr Data'!IW$4:IW$103,"<>"&0)*ToC!$E$15/ToC!$E$10 -> -15879.96 | F14: =+SUMIFS('Quikirr Data'!IX$4:IX$103,'Quikirr Data'!IX$4:IX$103,"<>"&0)*ToC!$E$15/ToC!$E$10 -> -17079.12 | G14: =+SUMIFS('Quikirr Data'!IY$4:IY$103,'Quikirr Data'!IY$4:IY$103,"<>"&0)*ToC!$E$15/ToC!$E$10 -> -19614.72 | H14: =+SUMIFS('Quikirr Data'!IZ$4:IZ$103,'Quikirr Data'!IZ$4:IZ$103,"<>"&0)*ToC!$E$15/ToC!$E$10 -> -19345.8 | I14: =+SUMIFS('Quikirr Data'!JA$4:JA$103,'Quikirr Data'!JA$4:JA$103,"<>"&0)*ToC!$E$15/ToC!$E$10 -> -20768.88 | J14: =+SUMIFS('Quikirr Data'!JB$4:JB$103,'Quikirr Data'!JB$4:JB$103,"<>"&0)*ToC!$E$15/ToC!$E$10 -> -20988.6 | K14: =+SUMIFS('Quikirr Data'!JC$4:JC$103,'Quikirr Data'!JC$4:JC$103,"<>"&0)*ToC!$E$15/ToC!$E$10 -> -20925 | ... AB14: =+SUMIFS('Quikirr Data'!JT$4:JT$103,'Quikirr Data'!JT$4:JT$103,"<>"&0)*ToC!$E$15/ToC!$E$10 -> -4536
C15: EoP ARR | D15: =+SUM(D10:D14) -> 214713.6 | E15: =+SUM(E10:E14) -> 215670.12 | F15: =+SUM(F10:F14) -> 215676.6 | G15: =+SUM(G10:G14) -> 213660.6 | H15: =+SUM(H10:H14) -> 213351 | I15: =+SUM(I10:I14) -> 212321.4 | J15: =+SUM(J10:J14) -> 212321.4 | K15: =+SUM(K10:K14) -> 221419.2 | ... AB15: =+SUM(AB10:AB14) -> 244817.4
C17: New % of BoP | D17: =+IFERROR(D11/D10,0) -> 0.06929713 | E17: =+IFERROR(E11/E10,0) -> 0.06929713 | F17: =+IFERROR(F11/F10,0) -> 0.069960166 | G17: =+IFERROR(G11/G10,0) -> 0 | H17: =+IFERROR(H11/H10,0) -> 0 | I17: =+IFERROR(I11/I10,0) -> 0 | J17: =+IFERROR(J11/J10,0) -> 0 | K17: =+IFERROR(K11/K10,0) -> 0.056445253 | ... AB17: =+IFERROR(AB11/AB10,0) -> 0.10585484
C18: Upsell % of BoP | D18: =+IFERROR(D12/D10,0) -> 0.020181759 | E18: =+IFERROR(E12/E10,0) -> 0.028514212 | F18: =+IFERROR(F12/F10,0) -> 0.030358432 | G18: =+IFERROR(G12/G10,0) -> 0.028550179 | H18: =+IFERROR(H12/H10,0) -> 0.027108819 | I18: =+IFERROR(I12/I10,0) -> 0.029964442 | J18: =+IFERROR(J12/J10,0) -> 0.027892046 | K18: =+IFERROR(K12/K10,0) -> 0.030250063 | ... AB18: =+IFERROR(AB12/AB10,0) -> 0.026495957
C19: (Downsell) % of BoP | D19: =+IFERROR(D13/D10,0) -> -0.022028786 | E19: =+IFERROR(E13/E10,0) -> -0.025933374 | F19: =+IFERROR(F13/F10,0) -> -0.01255041 | G19: =+IFERROR(G13/G10,0) -> -0.013935573 | H19: =+IFERROR(H13/H10,0) -> -0.015664519 | I19: =+IFERROR(I13/I10,0) -> -0.01795845 | J19: =+IFERROR(J13/J10,0) -> -0.012536772 | K19: =+IFERROR(K13/K10,0) -> -0.0032131035 | ... AB19: =+IFERROR(AB13/AB10,0) -> -0.015595752
C20: (Churn) % of BoP | D20: =+IFERROR(D14/D10,0) -> -0.073510574 | E20: =+IFERROR(E14/E10,0) -> -0.073510574 | F20: =+IFERROR(F14/F10,0) -> -0.079818117 | G20: =+IFERROR(G14/G10,0) -> -0.085312846 | H20: =+IFERROR(H14/H10,0) -> -0.084088819 | I20: =+IFERROR(I14/I10,0) -> -0.090172061 | J20: =+IFERROR(J14/J10,0) -> -0.091341501 | K20: =+IFERROR(K14/K10,0) -> -0.093552333 | ... AB20: =+IFERROR(AB14/AB10,0) -> -0.020314946
C21: Gross Adds % of BoP | D21: =+IFERROR((SUM(D11:D12))/D10,0) -> 0.089478888 | E21: =+IFERROR((SUM(E11:E12))/E10,0) -> 0.097811342 | F21: =+IFERROR((SUM(F11:F12))/F10,0) -> 0.1003186 | G21: =+IFERROR((SUM(G11:G12))/G10,0) -> 0.028550179 | H21: =+IFERROR((SUM(H11:H12))/H10,0) -> 0.027108819 | I21: =+IFERROR((SUM(I11:I12))/I10,0) -> 0.029964442 | J21: =+IFERROR((SUM(J11:J12))/J10,0) -> 0.027892046 | K21: =+IFERROR((SUM(K11:K12))/K10,0) -> 0.086695316 | ... AB21: =+IFERROR((SUM(AB11:AB12))/AB10,0) -> 0.1323508
C22: Gross Losses % of BoP | D22: =+IFERROR((SUM(D13:D14))/D10,0) -> -0.09553936 | E22: =+IFERROR((SUM(E13:E14))/E10,0) -> -0.099443948 | F22: =+IFERROR((SUM(F13:F14))/F10,0) -> -0.092368527 | G22: =+IFERROR((SUM(G13:G14))/G10,0) -> -0.099248419 | H22: =+IFERROR((SUM(H13:H14))/H10,0) -> -0.099753338 | I22: =+IFERROR((SUM(I13:I14))/I10,0) -> -0.10813051 | J22: =+IFERROR((SUM(J13:J14))/J10,0) -> -0.10387827 | K22: =+IFERROR((SUM(K13:K14))/K10,0) -> -0.096765436 | ... AB22: =+IFERROR((SUM(AB13:AB14))/AB10,0) -> -0.035910698
C24: New % of Average | D24: =+IFERROR(D11/AVERAGE(D10,D15),0) -> 0.069507755 | E24: =+IFERROR(E11/AVERAGE(E10,E15),0) -> 0.069353743 | F24: =+IFERROR(F11/AVERAGE(F10,F15),0) -> 0.069683172 | G24: =+IFERROR(G11/AVERAGE(G10,G15),0) -> 0 | H24: =+IFERROR(H11/AVERAGE(H10,H15),0) -> 0 | I24: =+IFERROR(I11/AVERAGE(I10,I15),0) -> 0 | J24: =+IFERROR(J11/AVERAGE(J10,J15),0) -> 0 | K24: =+IFERROR(K11/AVERAGE(K10,K15),0) -> 0.056730896 | ... AB24: =+IFERROR(AB11/AVERAGE(AB10,AB15),0) -> 0.10098533
C25: Upsell % of Average | D25: =+IFERROR(D12/AVERAGE(D10,D15),0) -> 0.0202431 | E25: =+IFERROR(E12/AVERAGE(E10,E15),0) -> 0.028537508 | F25: =+IFERROR(F12/AVERAGE(F10,F15),0) -> 0.030238234 | G25: =+IFERROR(G12/AVERAGE(G10,G15),0) -> 0.029596385 | H25: =+IFERROR(H12/AVERAGE(H10,H15),0) -> 0.028130585 | I25: =+IFERROR(I12/AVERAGE(I10,I15),0) -> 0.031183175 | J25: =+IFERROR(J12/AVERAGE(J10,J15),0) -> 0.028993603 | K25: =+IFERROR(K12/AVERAGE(K10,K15),0) -> 0.030403145 | ... AB25: =+IFERROR(AB12/AVERAGE(AB10,AB15),0) -> 0.025277094
C26: (Downsell) % of Average | D26: =+IFERROR(D13/AVERAGE(D10,D15),0) -> -0.022095741 | E26: =+IFERROR(E13/AVERAGE(E10,E15),0) -> -0.02595456 | F26: =+IFERROR(F13/AVERAGE(F10,F15),0) -> -0.012500719 | G26: =+IFERROR(G13/AVERAGE(G10,G15),0) -> -0.014446234 | H26: =+IFERROR(H13/AVERAGE(H10,H15),0) -> -0.016254935 | I26: =+IFERROR(I13/AVERAGE(I10,I15),0) -> -0.018688868 | J26: =+IFERROR(J13/AVERAGE(J10,J15),0) -> -0.013031894 | K26: =+IFERROR(K13/AVERAGE(K10,K15),0) -> -0.0032293635 | ... AB26: =+IFERROR(AB13/AVERAGE(AB10,AB15),0) -> -0.014878319
C27: (Churn) % of Average | D27: =+IFERROR(D14/AVERAGE(D10,D15),0) -> -0.073734005 | E27: =+IFERROR(E14/AVERAGE(E10,E15),0) -> -0.07357063 | F27: =+IFERROR(F14/AVERAGE(F10,F15),0) -> -0.079502094 | G27: =+IFERROR(G14/AVERAGE(G10,G15),0) -> -0.08843909 | H27: =+IFERROR(H14/AVERAGE(H10,H15),0) -> -0.087258235 | I27: =+IFERROR(I14/AVERAGE(I10,I15),0) -> -0.093839597 | J27: =+IFERROR(J14/AVERAGE(J10,J15),0) -> -0.094948906 | K27: =+IFERROR(K14/AVERAGE(K10,K15),0) -> -0.094025758 | ... AB27: =+IFERROR(AB14/AVERAGE(AB10,AB15),0) -> -0.019380421
C28: Gross Adds % of Average | D28: =+IFERROR((SUM(D11:D12))/AVERAGE(D10,D15),0) -> 0.089750855 | E28: =+IFERROR((SUM(E11:E12))/AVERAGE(E10,E15),0) -> 0.097891251 | F28: =+IFERROR((SUM(F11:F12))/AVERAGE(F10,F15),0) -> 0.099921406 | G28: =+IFERROR((SUM(G11:G12))/AVERAGE(G10,G15),0) -> 0.029596385 | H28: =+IFERROR((SUM(H11:H12))/AVERAGE(H10,H15),0) -> 0.028130585 | I28: =+IFERROR((SUM(I11:I12))/AVERAGE(I10,I15),0) -> 0.031183175 | J28: =+IFERROR((SUM(J11:J12))/AVERAGE(J10,J15),0) -> 0.028993603 | K28: =+IFERROR((SUM(K11:K12))/AVERAGE(K10,K15),0) -> 0.087134041 | ... AB28: =+IFERROR((SUM(AB11:AB12))/AVERAGE(AB10,AB15),0) -> 0.12626242
C29: Gross Losses % of Average | D29: =+IFERROR((SUM(D13:D14))/AVERAGE(D10,D15),0) -> -0.095829746 | E29: =+IFERROR((SUM(E13:E14))/AVERAGE(E10,E15),0) -> -0.09952519 | F29: =+IFERROR((SUM(F13:F14))/AVERAGE(F10,F15),0) -> -0.092002813 | G29: =+IFERROR((SUM(G13:G14))/AVERAGE(G10,G15),0) -> -0.10288532 | H29: =+IFERROR((SUM(H13:H14))/AVERAGE(H10,H15),0) -> -0.10351317 | I29: =+IFERROR((SUM(I13:I14))/AVERAGE(I10,I15),0) -> -0.11252847 | J29: =+IFERROR((SUM(J13:J14))/AVERAGE(J10,J15),0) -> -0.1079808 | K29: =+IFERROR((SUM(K13:K14))/AVERAGE(K10,K15),0) -> -0.097255122 | ... AB29: =+IFERROR((SUM(AB13:AB14))/AVERAGE(AB10,AB15),0) -> -0.03425874
C31: % Growth New (YoY) | P31: =+IFERROR(P11/D11-1,0) -> -0.15661975 | Q31: =+IFERROR(Q11/E11-1,0) -> -0.15661975 | R31: =+IFERROR(R11/F11-1,0) -> -0.15661975 | S31: =+IFERROR(S11/G11-1,0) -> 0 | T31: =+IFERROR(T11/H11-1,0) -> 0 | U31: =+IFERROR(U11/I11-1,0) -> 0 | V31: =+IFERROR(V11/J11-1,0) -> 0 | W31: =+IFERROR(W11/K11-1,0) -> 0.87210341 | ... AB31: =+IFERROR(AB11/P11-1,0) -> 0.87210341
C32: % Growth Upsell (YoY) | P32: =+IFERROR(P12/D12-1,0) -> -0.055517327 | Q32: =+IFERROR(Q12/E12-1,0) -> -0.54832363 | R32: =+IFERROR(R12/F12-1,0) -> -0.58879057 | S32: =+IFERROR(S12/G12-1,0) -> -0.36094404 | T32: =+IFERROR(T12/H12-1,0) -> -0.29365247 | U32: =+IFERROR(U12/I12-1,0) -> -0.31130353 | V32: =+IFERROR(V12/J12-1,0) -> -0.12819937 | W32: =+IFERROR(W12/K12-1,0) -> -0.039532491 | ... AB32: =+IFERROR(AB12/P12-1,0) -> 0.43676051
C33: % Growth New + Upsell (YoY) | P33: =+IFERROR(P39/D39-1,0) -> -0.13381633 | Q33: =+IFERROR(Q39/E39-1,0) -> -0.27081026 | R33: =+IFERROR(R39/F39-1,0) -> -0.28740336 | S33: =+IFERROR(S39/G39-1,0) -> 1.6253451 | T33: =+IFERROR(T39/H39-1,0) -> 1.7968945 | U33: =+IFERROR(U39/I39-1,0) -> 1.5778694 | V33: =+IFERROR(V39/J39-1,0) -> 5.5939823 | W33: =+IFERROR(W39/K39-1,0) -> 0.55401191 | ... AB33: =+IFERROR(AB39/P39-1,0) -> 0.76503684
C34: % Growth Churn (YoY) | P34: =+IFERROR(P14/D14-1,0) -> -0.52014992 | Q34: =+IFERROR(Q14/E14-1,0) -> -0.37754755 | R34: =+IFERROR(R14/F14-1,0) -> -0.37186459 | S34: =+IFERROR(S14/G14-1,0) -> -0.53137236 | T34: =+IFERROR(T14/H14-1,0) -> -0.54086158 | U34: =+IFERROR(U14/I14-1,0) -> -0.63194934 | V34: =+IFERROR(V14/J14-1,0) -> -0.63580229 | W34: =+IFERROR(W14/K14-1,0) -> -0.79469534 | ... AB34: =+IFERROR(AB14/P14-1,0) -> -0.40472441
C35: % Growth Downsell + Churn (YoY) | P35: =+IFERROR(P40/D40-1,0) -> -0.60401537 | Q35: =+IFERROR(Q40/E40-1,0) -> -0.44642438 | R35: =+IFERROR(R40/F40-1,0) -> -0.39831821 | S35: =+IFERROR(S40/G40-1,0) -> -0.49388923 | T35: =+IFERROR(T40/H40-1,0) -> -0.51026683 | U35: =+IFERROR(U40/I40-1,0) -> -0.55749893 | V35: =+IFERROR(V40/J40-1,0) -> -0.53829602 | W35: =+IFERROR(W40/K40-1,0) -> -0.64882127 | ... AB35: =+IFERROR(AB40/P40-1,0) -> -0.018882608
C37: % Growth | D37: =+IFERROR(D15/D10-1,0) -> -0.0060604714 | E37: =+IFERROR(E15/E10-1,0) -> -0.0016326054 | F37: =+IFERROR(F15/F10-1,0) -> 0.0079500698 | G37: =+IFERROR(G15/G10-1,0) -> -0.07069824 | H37: =+IFERROR(H15/H10-1,0) -> -0.072644519 | I37: =+IFERROR(I15/I10-1,0) -> -0.07816607 | J37: =+IFERROR(J15/J10-1,0) -> -0.075986228 | K37: =+IFERROR(K15/K10-1,0) -> -0.010070121 | ... AB37: =+IFERROR(AB15/AB10-1,0) -> 0.096440101
C38: Net New ARR | D38: =+D15-D10 -> -1309.2 | E38: =+E15-E10 -> -352.68 | F38: =+F15-F10 -> 1701.12 | G38: =+G15-G10 -> -16254.6 | H38: =+H15-H10 -> -16712.88 | I38: =+I15-I10 -> -18003.6 | J38: =+J15-J10 -> -17460.24 | K38: =+K15-K10 -> -2252.4 | ... AB38: =+AB15-AB10 -> 21533.52
C39: New + Upsell | D39: =+SUM(D11:D12) -> 19329.48 | E39: =+SUM(E11:E12) -> 21129.48 | F39: =+SUM(F11:F12) -> 21465.72 | G39: =+SUM(G11:G12) -> 6564.12 | H39: =+SUM(H11:H12) -> 6236.76 | I39: =+SUM(I11:I12) -> 6901.56 | J39: =+SUM(J11:J12) -> 6409.08 | K39: =+SUM(K11:K12) -> 19391.28 | ... AB39: =+SUM(AB11:AB12) -> 29551.8
C40: Downsell + Churn | D40: =+SUM(D13:D14) -> -20638.68 | E40: =+SUM(E13:E14) -> -21482.16 | F40: =+SUM(F13:F14) -> -19764.6 | G40: =+SUM(G13:G14) -> -22818.72 | H40: =+SUM(H13:H14) -> -22949.64 | I40: =+SUM(I13:I14) -> -24905.16 | J40: =+SUM(J13:J14) -> -23869.32 | K40: =+SUM(K13:K14) -> -21643.68 | ... AB40: =+SUM(AB13:AB14) -> -8018.28
C42: Gross Retention % | D42: =+IFERROR((SUM(D10,D13:D14)/D10),0) -> 0.90446064 | E42: =+IFERROR((SUM(E10,E13:E14)/E10),0) -> 0.90055605 | F42: =+IFERROR((SUM(F10,F13:F14)/F10),0) -> 0.90763147 | G42: =+IFERROR((SUM(G10,G13:G14)/G10),0) -> 0.90075158 | H42: =+IFERROR((SUM(H10,H13:H14)/H10),0) -> 0.90024666 | I42: =+IFERROR((SUM(I10,I13:I14)/I10),0) -> 0.89186949 | J42: =+IFERROR((SUM(J10,J13:J14)/J10),0) -> 0.89612173 | K42: =+IFERROR((SUM(K10,K13:K14)/K10),0) -> 0.90323456 | ... AB42: =+IFERROR((SUM(AB10,AB13:AB14)/AB10),0) -> 0.9640893
C43: Loss-Only Retention % | D43: =+IFERROR((SUM(D10,D14)/D10),0) -> 0.92648943 | E43: =+IFERROR((SUM(E10,E14)/E10),0) -> 0.92648943 | F43: =+IFERROR((SUM(F10,F14)/F10),0) -> 0.92018188 | G43: =+IFERROR((SUM(G10,G14)/G10),0) -> 0.91468715 | H43: =+IFERROR((SUM(H10,H14)/H10),0) -> 0.91591118 | I43: =+IFERROR((SUM(I10,I14)/I10),0) -> 0.90982794 | J43: =+IFERROR((SUM(J10,J14)/J10),0) -> 0.9086585 | K43: =+IFERROR((SUM(K10,K14)/K10),0) -> 0.90644767 | ... AB43: =+IFERROR((SUM(AB10,AB14)/AB10),0) -> 0.97968505
C44: Net Retention % | D44: =+IFERROR((SUM(D10,D12:D14)/D10),0) -> 0.9246424 | E44: =+IFERROR((SUM(E10,E12:E14)/E10),0) -> 0.92907026 | F44: =+IFERROR((SUM(F10,F12:F14)/F10),0) -> 0.9379899 | G44: =+IFERROR((SUM(G10,G12:G14)/G10),0) -> 0.92930176 | H44: =+IFERROR((SUM(H10,H12:H14)/H10),0) -> 0.92735548 | I44: =+IFERROR((SUM(I10,I12:I14)/I10),0) -> 0.92183393 | J44: =+IFERROR((SUM(J10,J12:J14)/J10),0) -> 0.92401377 | K44: =+IFERROR((SUM(K10,K12:K14)/K10),0) -> 0.93348463 | ... AB44: =+IFERROR((SUM(AB10,AB12:AB14)/AB10),0) -> 0.99058526
C46: Customer Waterfall
C48: BoP Customers | D48: =+COUNTIFS('Quikirr Data'!C$4:C$103,">"&0) -> 79 | E48: =+COUNTIFS('Quikirr Data'!D$4:D$103,">"&0) -> 79 | F48: =+COUNTIFS('Quikirr Data'!E$4:E$103,">"&0) -> 79 | G48: =+COUNTIFS('Quikirr Data'!F$4:F$103,">"&0) -> 86 | H48: =+COUNTIFS('Quikirr Data'!G$4:G$103,">"&0) -> 86 | I48: =+COUNTIFS('Quikirr Data'!H$4:H$103,">"&0) -> 86 | J48: =+COUNTIFS('Quikirr Data'!I$4:I$103,">"&0) -> 86 | K48: =+COUNTIFS('Quikirr Data'!J$4:J$103,">"&0) -> 86 | ... AB48: =+COUNTIFS('Quikirr Data'!AA$4:AA$103,">"&0) -> 80
A49: NEW | C49: New | D49: =+COUNTIFS('Quikirr Data'!HV$4:HV$103,">"&0) -> 6 | E49: =+COUNTIFS('Quikirr Data'!HW$4:HW$103,">"&0) -> 6 | F49: =+COUNTIFS('Quikirr Data'!HX$4:HX$103,">"&0) -> 6 | G49: =+COUNTIFS('Quikirr Data'!HY$4:HY$103,">"&0) -> 0 | H49: =+COUNTIFS('Quikirr Data'!HZ$4:HZ$103,">"&0) -> 0 | I49: =+COUNTIFS('Quikirr Data'!IA$4:IA$103,">"&0) -> 0 | J49: =+COUNTIFS('Quikirr Data'!IB$4:IB$103,">"&0) -> 0 | K49: =+COUNTIFS('Quikirr Data'!IC$4:IC$103,">"&0) -> 5 | ... AB49: =+COUNTIFS('Quikirr Data'!IT$4:IT$103,">"&0) -> 7
A50: CHURN | C50: (Churn) | D50: =+COUNTIFS('Quikirr Data'!IV$4:IV$103,"<"&0)*-1 -> -6 | E50: =+COUNTIFS('Quikirr Data'!IW$4:IW$103,"<"&0)*-1 -> -6 | F50: =+COUNTIFS('Quikirr Data'!IX$4:IX$103,"<"&0)*-1 -> -7 | G50: =+COUNTIFS('Quikirr Data'!IY$4:IY$103,"<"&0)*-1 -> -9 | H50: =+COUNTIFS('Quikirr Data'!IZ$4:IZ$103,"<"&0)*-1 -> -9 | I50: =+COUNTIFS('Quikirr Data'!JA$4:JA$103,"<"&0)*-1 -> -10 | J50: =+COUNTIFS('Quikirr Data'!JB$4:JB$103,"<"&0)*-1 -> -10 | K50: =+COUNTIFS('Quikirr Data'!JC$4:JC$103,"<"&0)*-1 -> -11 | ... AB50: =+COUNTIFS('Quikirr Data'!JT$4:JT$103,"<"&0)*-1 -> -2
C51: EoP Customers | D51: =+SUM(D48:D50) -> 79 | E51: =+SUM(E48:E50) -> 79 | F51: =+SUM(F48:F50) -> 78 | G51: =+SUM(G48:G50) -> 77 | H51: =+SUM(H48:H50) -> 77 | I51: =+SUM(I48:I50) -> 76 | J51: =+SUM(J48:J50) -> 76 | K51: =+SUM(K48:K50) -> 80 | ... AB51: =+SUM(AB48:AB50) -> 85
C53: Net Logos Added | D53: =+SUM(D49:D50) -> 0 | E53: =+SUM(E49:E50) -> 0 | F53: =+SUM(F49:F50) -> -1 | G53: =+SUM(G49:G50) -> -9 | H53: =+SUM(H49:H50) -> -9 | I53: =+SUM(I49:I50) -> -10 | J53: =+SUM(J49:J50) -> -10 | K53: =+SUM(K49:K50) -> -6 | ... AB53: =+SUM(AB49:AB50) -> 5
C54: Logo % Growth | D54: =+IFERROR(D51/D48-1,0) -> 0 | E54: =+IFERROR(E51/E48-1,0) -> 0 | F54: =+IFERROR(F51/F48-1,0) -> -0.012658228 | G54: =+IFERROR(G51/G48-1,0) -> -0.10465116 | H54: =+IFERROR(H51/H48-1,0) -> -0.10465116 | I54: =+IFERROR(I51/I48-1,0) -> -0.11627907 | J54: =+IFERROR(J51/J48-1,0) -> -0.11627907 | K54: =+IFERROR(K51/K48-1,0) -> -0.069767442 | ... AB54: =+IFERROR(AB51/AB48-1,0) -> 0.0625
...

Sheet Customers >

Sheet Top Customers
C2: Rank As Of
C3: 46022
C4: 46022
C5: 45657
C6: 45291
C7: 44926
C9: ="Top Customers as of " & TEXT('Top Customers'!C3, "mmm-yy") -> Top Customers as of Dec-25
C10: ="("&ToC!$E$12&" "&ToC!$E$11&")" -> ($ Actuals)
F11: ARR | O11: $ Growth | U11: % Growth
C12: Rank | D12: Customer | F12: 44926 | G12: 45291 | H12: 45657 | I12: 46022 | K12: =TEXT($F$12,"mmm 'yy")&" - "&TEXT($I$12,"mmm 'yy")&" CAGR" -> Dec '22 - Dec '25 CAGR | L12: ="% of "&TEXT($I$12,"mmm 'yy")&" ARR" -> % of Dec '25 ARR | M12: % Total Cum. | O12: =TEXT($F$12,"mmm 'yy")&" - "&TEXT($G$12,"mmm 'yy") -> Dec '22 - Dec '23 | P12: =TEXT($G$12,"mmm 'yy")&" - "&TEXT($H$12,"mmm 'yy") -> Dec '23 - Dec '24 | Q12: =TEXT($H$12,"mmm 'yy")&" - "&TEXT($I$12,"mmm 'yy") -> Dec '24 - Dec '25 | R12: ="% of "&$Q$12&" Growth" -> % of Dec '24 - Dec '25 Growth | S12: Mult. of Initial | U12: =TEXT($F$12,"mmm 'yy")&" - "&TEXT($G$12,"mmm 'yy") -> Dec '22 - Dec '23 | V12: =TEXT($G$12,"mmm 'yy")&" - "&TEXT($H$12,"mmm 'yy") -> Dec '23 - Dec '24 | W12: =TEXT($H$12,"mmm 'yy")&" - "&TEXT($I$12,"mmm 'yy") -> Dec '24 - Dec '25 | Y12: Customer Since
C14: 1 | D14: =+IFERROR(INDEX('Quikirr Data'!$B$4:$B$103,MATCH($C14,'Quikirr Data'!$NB$4:$NB$103,0),1),"") -> 61 | F14: =+IFERROR(INDEX('Quikirr Data'!$C$4:$AM$103,MATCH($C14,'Quikirr Data'!$NB$4:$NB$103,0),MATCH(F$12,'Quikirr Data'!$C$3:$AM$3,0)),0)*ToC!$E$15/ToC!$E$10 -> 4644 | G14: =+IFERROR(INDEX('Quikirr Data'!$C$4:$AM$103,MATCH($C14,'Quikirr Data'!$NB$4:$NB$103,0),MATCH(G$12,'Quikirr Data'!$C$3:$AM$3,0)),0)*ToC!$E$15/ToC!$E$10 -> 4644 | H14: =+IFERROR(INDEX('Quikirr Data'!$C$4:$AM$103,MATCH($C14,'Quikirr Data'!$NB$4:$NB$103,0),MATCH(H$12,'Quikirr Data'!$C$3:$AM$3,0)),0)*ToC!$E$15/ToC!$E$10 -> 4644 | I14: =+IFERROR(INDEX('Quikirr Data'!$C$4:$AM$103,MATCH($C14,'Quikirr Data'!$NB$4:$NB$103,0),MATCH(I$12,'Quikirr Data'!$C$3:$AM$3,0)),0)*ToC!$E$15/ToC!$E$10 -> 4798.56 | K14: =+IFERROR((I14/F14)^(1/YEARFRAC($F$12,$I$12))-1,0) -> 0.010973037 | L14: =+IFERROR(I14/I$27,0) -> 0.019600568 | M14: =+IFERROR(SUM(I$14:I14)/I$27,0) -> 0.019600568 | O14: =+G14-F14 -> 0 | P14: =+H14-G14 -> 0 | Q14: =+I14-H14 -> 154.56 | R14: {=+IFERROR(INDEX($O14:$Q14,MAX(MATCH('Top Customers'!$C$3,$F$12:$I$12,0)-1,1))/INDEX($O$27:$Q$27,MAX(MATCH('Top Customers'!$C$3,$F$12:$I$12,0)-1,1)),0)} -> 0.0071776468 | S14: {=+IFERROR(I14/INDEX($F14:$I14,MATCH(TRUE,$F14:$I14<>0,0)),0)} -> 1.0332817 | U14: =+IFERROR(G14/F14-1,0) -> 0 | V14: =+IFERROR(H14/G14-1,0) -> 0 | W14: =+IFERROR(I14/H14-1,0) -> 0.033281654 | Y14: {=+IFERROR(INDEX('Quikirr Data'!$BD$4:$BD$103, MATCH(1,('Quikirr Data'!$B$4:$B$103=$D14)*('Quikirr Data'!$NB$4:$NB$103=$C14),0), 1),"N/A")} -> 44926
